Workbook

Sheet Sheet1
A1: 📘 Most Common RAR Codes for Non-Covered Denials (Deep Explanation)
A5: 1️⃣ N115 — Service Not Covered Unless Medical Criteria Met
A7: Meaning
A9: Service may be covered only if medical necessity guidelines are met, but payer determined criteria were not satisfied.
A11: Real Scenarios
A13: MRI without conservative therapy documentation
A15: Lab test without supporting diagnosis
A17: Sleep study without symptoms
A19: Therapy beyond allowed visits without justification
A21: Root Cause
A23: Diagnosis not supporting CPT
A25: Missing documentation
... A381: EMR integration

Sheet Sheet2
A1: CARC CODE | B1: DENIAL REASON | C1: RARC / REMARKS | D1: MEANING & EXAMPLES | E1: REAL SCENARIOS | F1: ROOT CAUSE | G1: RESOLUTION STEPS | H1: Code
A2: CO 18 | B2: Duplicate | C2: N522 — Duplicate of a claim processed, as a crossover claim. | D2: The claim is an exact duplicate of one already processed or in process (same patient, date of service, provider, codes, etc.). No payment issued; often seen in general duplicates or Medicare crossover cases where claim was auto-forwarded. | E2: • Resubmitted identical claim by mistake or due to system glitch. • Billed same procedure twice without modifier (e.g., two identical office visits same day). • Submitted to secondary payer while primary (e.g., Medicare) processes/crossover pending. • Billing system auto-follow-up triggered duplicate. • Corrected claim sent without proper replacement indicator. | F2: • Provider billed secondary payer prematurely before crossover completed • Duplicate claim submission from billing system • Patient insurance sequence not verified properly | G2: • Check Medicare crossover confirmation (ERA/EOB remark) • Confirm if secondary payer received claim via crossover • Do not rebill if crossover pending or completed • Rebill only if crossover failed and payer confirms resubmission required • Adjust duplicate claim if already processed | H2: =SUBSTITUTE( "<tr data-carc=""" & A2 & """ data-rarc=""" & C2 & """" & CHAR(10) & " data-denial=""" & SUBSTITUTE(TRIM(D2),CHAR(10),"\n") & """" & CHAR(10) & " data-root=""" & SUBSTITUTE(TRIM(F2),CHAR(10),"\n") & """>" & CHAR(10) & " <td><span class=""carc-badge co"">" & A2 & "</span></td>" & CHAR(10) & " <td style=""font-weight:500;"">" & B2 & "</td>" & CHAR(10) & " <td class=""rarc-wrap""><div class=""rarc-id"">" & LEFT(C2,FIND(" ",C2)-1) & "</div><div class=""rarc-desc"">" & TRIM(MID(C2,FIND("—",C2)+1,999)) & "</div></td>" & CHAR(10) & " <td class=""td-sm"">" & SUBSTITUTE(TRIM(D2),CHAR(10),"<br>") & "</td>" & CHAR(10) & " <td><div class=""chip-row""><span class=""chip chip-red"">" & SUBSTITUTE(SUBSTITUTE(SUBSTITUTE(TRIM(E2),"• ",""),CHAR(10),"|"),"|", "</span><span class=""chip chip-red"">") & "</span></div></td>" & CHAR(10) & " <td><div class=""chip-row""><span class=""chip chip-red"">" & SUBSTITUTE(SUBSTITUTE(SUBSTITUTE(TRIM(F2),"• ",""),CHAR(10),"|"),"|", "</span><span class=""chip chip-red"">") & "</span></div></td>" & CHAR(10) & " <td class=""td-sm"">" & SUBSTITUTE(TRIM(G2),CHAR(10),"<br>") & "</td>" & CHAR(10) & " </tr>","""","""") -> <tr data-carc="CO 18" data-rarc="N522 — Duplicate of a claim processed, as a crossover claim." data-denial="The claim is an exact duplicate of one already processed or in process (same patient, date of service, provider, codes, etc.). No payment issued; often seen in general duplicates or Medicare crossover cases where claim was auto-forwarded." data-root="• Provider billed secondary payer prematurely before crossover completed\n• Duplicate claim submission from billing system\n• Patient insurance sequence not verified properly"> <td><span class="carc-badge co">CO 18</span></td> <td style="font-weight:500;">Duplicate</td> <td class="rarc-wrap"><div class="rarc-id">N522</div><div class="rarc-desc">Duplicate of a claim processed, as a crossover claim.</div></td> <td class="td-sm">The claim is an exact duplicate of one already processed or in process (same patient, date of service, provider, codes, etc.). No payment issued; often seen in general duplicates or Medicare crossover cases where claim was auto-forwarded.</td> <td><div class="chip-row"><span class="chip chip-red">Resubmitted identical claim by mistake or due to system glitch.</span><span class="chip chip-red">Billed same procedure twice without modifier (e.g., two identical office visits same day).</span><span class="chip chip-red">Submitted to secondary payer while primary (e.g., Medicare) processes/crossover pending.</span><span class="chip chip-red">Billing system auto-follow-up triggered duplicate.</span><span class="chip chip-red">Corrected claim sent without proper replacement indicator.</span></div></td> <td><div class="chip-row"><span class="chip chip-red">Provider billed secondary payer prematurely before crossover completed</span><span class="chip chip-red">Duplicate claim submission from billing system</span><span class="chip chip-red">Patient insurance sequence not verified properly</span></div></td> <td class="td-sm">• Check Medicare crossover confirmation (ERA/EOB remark)<br>• Confirm if secondary payer received claim via crossover<br>• Do not rebill if crossover pending or completed<br>• Rebill only if crossover failed and payer confirms resubmission required<br>• Adjust duplicate claim if already processed</td> </tr>
A3: PR 1 | B3: Deductible Amount | C3: PR (Patient Responsibility) | D3: The payer applied the allowed amount (or portion) to the patient's annual deductible. The patient is responsible for this amount until the deductible is met; no payer payment issued for that portion. | E3: • Patient has not met their yearly deductible (e.g., $1,500 plan deductible; first claims of the year applied here). High-deductible health plan (HDHP) services billed early in the year. • Secondary payer applies after primary meets its deductible. Claim for preventive service that doesn't count toward deductible, but others do. • Billing system shows zero payer payment due to unmet deductible. | F3: Patient hasn't met deductible yet (common at start of plan year or high-deductible plans). Incorrect eligibility verification missing deductible status. Failure to collect estimated patient responsibility upfront. Coordination of benefits (COB) where primary deductible not satisfied. | G3: ✔ Verify patient deductible status via eligibility check/portal (pre-service). ✔ Bill patient directly for the PR-1 amount (post to patient ledger). ✔ If error (e.g., deductible already met), appeal with proof from payer. ✔ Collect payment from patient or set up payment plan. ✔ Update billing system with correct deductible info for future claims. | H3: =SUBSTITUTE( "<tr data-carc=""" & A3 & """ data-rarc=""" & C3 & """" & CHAR(10) & " data-denial=""" & SUBSTITUTE(TRIM(D3),CHAR(10),"\n") & """" & CHAR(10) & " data-root=""" & SUBSTITUTE(TRIM(F3),CHAR(10),"\n") & """>" & CHAR(10) & " <td><span class=""carc-badge co"">" & A3 & "</span></td>" & CHAR(10) & " <td style=""font-weight:500;"">" & B3 & "</td>" & CHAR(10) & " <td class=""rarc-wrap""><div class=""rarc-id"">" & LEFT(C3,FIND(" ",C3)-1) & "</div><div class=""rarc-desc"">" & TRIM(MID(C3,FIND("—",C3)+1,999)) & "</div></td>" & CHAR(10) & " <td class=""td-sm"">" & SUBSTITUTE(TRIM(D3),CHAR(10),"<br>") & "</td>" & CHAR(10) & " <td><div class=""chip-row""><span class=""chip chip-red"">" & SUBSTITUTE(SUBSTITUTE(SUBSTITUTE(TRIM(E3),"• ",""),CHAR(10),"|"),"|", "</span><span class=""chip chip-red"">") & "</span></div></td>" & CHAR(10) & " <td><div class=""chip-row""><span class=""chip chip-red"">" & SUBSTITUTE(SUBSTITUTE(SUBSTITUTE(TRIM(F3),"• ",""),CHAR(10),"|"),"|", "</span><span class=""chip chip-red"">") & "</span></div></td>" & CHAR(10) & " <td class=""td-sm"">" & SUBSTITUTE(TRIM(G3),CHAR(10),"<br>") & "</td>" & CHAR(10) & " </tr>","""","""") -> #VALUE!
A4: PR 2 | B4: Coinsurance Amount | C4: PR (Patient Responsibility) | D4: After deductible is met, the patient is responsible for their percentage share (coinsurance) of the allowed amount (e.g., 20% patient / 80% payer). Payer pays its portion; patient owes the rest. | E4: • Patient pays 20% coinsurance on specialist visit after deductible met. • Surgical procedure where plan is 80/20 after deductible. • Outpatient services with coinsurance applied to allowed amount. • Secondary payer coinsurance on remaining balance after primary payment. | F4: Standard plan design requires patient coinsurance share. Deductible met but coinsurance not collected upfront. Misunderstanding of plan benefits during eligibility check. COB where secondary applies coinsurance. | G4: ✔ Confirm coinsurance percentage via payer portal/eligibility. ✔ Bill patient for the PR-2 amount shown on EOB. ✔ If disputed (e.g., wrong percentage), appeal with benefit details. ✔ Post to patient account and follow up for payment. | H4: =SUBSTITUTE( "<tr data-carc=""" & A4 & """ data-rarc=""" & C4 & """" & CHAR(10) & " data-denial=""" & SUBSTITUTE(TRIM(D4),CHAR(10),"\n") & """" & CHAR(10) & " data-root=""" & SUBSTITUTE(TRIM(F4),CHAR(10),"\n") & """>" & CHAR(10) & " <td><span class=""carc-badge co"">" & A4 & "</span></td>" & CHAR(10) & " <td style=""font-weight:500;"">" & B4 & "</td>" & CHAR(10) & " <td class=""rarc-wrap""><div class=""rarc-id"">" & LEFT(C4,FIND(" ",C4)-1) & "</div><div class=""rarc-desc"">" & TRIM(MID(C4,FIND("—",C4)+1,999)) & "</div></td>" & CHAR(10) & " <td class=""td-sm"">" & SUBSTITUTE(TRIM(D4),CHAR(10),"<br>") & "</td>" & CHAR(10) & " <td><div class=""chip-row""><span class=""chip chip-red"">" & SUBSTITUTE(SUBSTITUTE(SUBSTITUTE(TRIM(E4),"• ",""),CHAR(10),"|"),"|", "</span><span class=""chip chip-red"">") & "</span></div></td>" & CHAR(10) & " <td><div class=""chip-row""><span class=""chip chip-red"">" & SUBSTITUTE(SUBSTITUTE(SUBSTITUTE(TRIM(F4),"• ",""),CHAR(10),"|"),"|", "</span><span class=""chip chip-red"">") & "</span></div></td>" & CHAR(10) & " <td class=""td-sm"">" & SUBSTITUTE(TRIM(G4),CHAR(10),"<br>") & "</td>" & CHAR(10) & " </tr>","""","""") -> #VALUE!
A5: PR 3 | B5: Copay Amount | C5: PR (Patient Responsibility) | D5: A fixed flat fee the patient must pay for a specific covered service (e.g., $30 office visit copay), regardless of allowed amount. Payer pays the balance after copay. | E5: • $25 copay for primary care visit. • $50 ER copay applied to emergency service. • Tiered copays (e.g., $10 generic Rx vs. $50 specialist). • Copay waived incorrectly for preventive care but applied elsewhere. | F5: Plan requires fixed copay per service type/visit. Copay not collected at time of service. Error in copay waiver verification (e.g., for preventive). Multiple visits/services triggering separate copays. | G5: ✔ Check EOB for exact copay amount and service applied to. ✔ Bill patient directly for PR-3 amount. ✔ If waiver error, appeal with documentation (e.g., preventive service). ✔ Pursue patient payment promptly. | H5: =SUBSTITUTE( "<tr data-carc=""" & A5 & """ data-rarc=""" & C5 & """" & CHAR(10) & " data-denial=""" & SUBSTITUTE(TRIM(D5),CHAR(10),"\n") & """" & CHAR(10) & " data-root=""" & SUBSTITUTE(TRIM(F5),CHAR(10),"\n") & """>" & CHAR(10) & " <td><span class=""carc-badge co"">" & A5 & "</span></td>" & CHAR(10) & " <td style=""font-weight:500;"">" & B5 & "</td>" & CHAR(10) & " <td class=""rarc-wrap""><div class=""rarc-id"">" & LEFT(C5,FIND(" ",C5)-1) & "</div><div class=""rarc-desc"">" & TRIM(MID(C5,FIND("—",C5)+1,999)) & "</div></td>" & CHAR(10) & " <td class=""td-sm"">" & SUBSTITUTE(TRIM(D5),CHAR(10),"<br>") & "</td>" & CHAR(10) & " <td><div class=""chip-row""><span class=""chip chip-red"">" & SUBSTITUTE(SUBSTITUTE(SUBSTITUTE(TRIM(E5),"• ",""),CHAR(10),"|"),"|", "</span><span class=""chip chip-red"">") & "</span></div></td>" & CHAR(10) & " <td><div class=""chip-row""><span class=""chip chip-red"">" & SUBSTITUTE(SUBSTITUTE(SUBSTITUTE(TRIM(F5),"• ",""),CHAR(10),"|"),"|", "</span><span class=""chip chip-red"">") & "</span></div></td>" & CHAR(10) & " <td class=""td-sm"">" & SUBSTITUTE(TRIM(G5),CHAR(10),"<br>") & "</td>" & CHAR(10) & " </tr>","""","""") -> #VALUE!

Sheet Calculate
A1: CARC | B1: Reason | C1: RARC | D1: MEANING & EXAMPLES | E1: REAL SCENARIOS | F1: ROOT CAUSE | G1: RESOLUTION STEPS | H1: Code | I1: With Formula Code
A2: CO 16 | B2: Additional Documentation Required to Process Claim | C2: N425—Additional documentation is needed to process this claim. At a minimum, send the information identified in this notice. | D2: The claim is pending or denied because the payer requires additional documentation to complete processing. This is not always a final denial—it is often a request for information (RFI) indicating that the payer cannot determine: Medical necessity Eligibility Authorization compliance Accuracy of billed services The payer will typically specify minimum required documents in the notice. Failure to submit the requested information within the timeframe may result in a full denial. | E2: Payer requests medical records for review → documentation not submitted → claim denied. Operative report required for procedure validation → missing → claim pended. Authorization proof requested but not provided → processing delayed. Incomplete clinical notes submitted → insufficient → denial issued. Incorrect documents uploaded (wrong patient/encounter) → claim not processed. | F2: Visits exceed physician-certified limits. Plan of care not updated or recertified. Mismatch between documentation and billing. Failure to track authorized visit counts. Staff unaware of certification limitations. | G2: Review payer notice to identify required documentation. Collect all relevant records, such as: Progress notes Operative reports Physician orders Authorization details Test results Validate documentation for completeness and accuracy. Submit documents via correct payer channel (portal, fax, EDI). Include claim reference details (claim number, patient info). Track submission and confirm receipt. Follow up until claim is processed. | I2: <tr data-carc="" data-type="" data-rarc="N425 — Statutorily excluded service(s)." data-denial="" data-root=""><td><div class="row-num">#561</div><span class="carc-badge "></span></td><td><span class="denial-reason"></span></td><td class="rarc-wrap"><div class="rarc-id">N425</div><div class="rarc-desc">Statutorily excluded service(s).</div></td><td class="td-meaning"></td><td><div class="chip-row"></div></td><td><div class="chip-row"></div></td><td class="td-res"></td></tr>
A3: CO 4 | B3: Add-on code | C3: N122—Missing/incomplete/invalid length of transport | D3: The claim was denied because an add-on procedure code (+ symbol in CPT, e.g., +11045, +69990) was billed alone without its required primary/base procedure code on the same claim. Add-on codes are never payable independently; they must accompany the primary service they supplement. | E3: • 49568 (hernia mesh implantation) billed alone without a primary hernia repair code (e.g., 49560–49566) → denied. • 15777 (grafting for wound closure) submitted without the primary closure/reconstruction code (e.g., 13100–13160 series). • 69990 (microsurgical techniques) billed by itself instead of with the primary neurosurgical or ENT procedure. • 99199 (unlisted special service) or +95972 (complex programming of neurostimulator) submitted standalone → rejected. • 95971 (simple programming of neurostimulator) billed without the primary implantation code (e.g., 64555, 64561). • Anesthesia add-on time code or time-based add-on (e.g., +99354 prolonged service) submitted without base code. | F3: • Add-on code (+XXXXX) submitted without corresponding primary/base procedure code. • Primary code omitted, on different claim, or not billed on same date of service. • Billing software or manual entry error (add-on code selected alone). • Provider unaware add-on codes require primary code on same claim. • Coding error: Misidentifying an add-on code as standalone or forgetting to pair it. • Claim split or resubmission error: Primary code processed earlier; add-on billed later without reference. • Lack of pre-billing check for required primary code linkage per CPT guidelines. | G3: • Identify add-on code from EOB and confirm primary code needed (CPT book or NCCI lookup). • Verify primary procedure was performed and billed (same DOS, same claim). • Resubmit corrected claim including both primary and add-on codes (frequency 7). • If primary code already billed separately → appeal with claim history and documentation showing linkage. • Accept denial if no primary procedure performed (post write-off). | I3: <tr data-carc="CO 4" data-type="co" data-rarc="N122 — Add-on code cannot be billed by itself." data-denial="The claim was denied because an add-on procedure code (+ symbol in CPT, e.g., +11045, +69990) was billed alone without its required primary/base procedure code on the same claim. Add-on codes are never payable independently; they must accompany the primary service they supplement." data-root="• Add-on code (+XXXXX) submitted without corresponding primary/base procedure code.\n• Primary code omitted, on different claim, or not billed on same date of service.\n• Billing software or manual entry error (add-on code selected alone).\n• Provider unaware add-on codes require primary code on same claim.\n• Coding error: Misidentifying an add-on code as standalone or forgetting to pair it.\n• Claim split or resubmission error: Primary code processed earlier; add-on billed later without reference.\n• Lack of pre-billing check for required primary code linkage per CPT guidelines."><td><div class="row-num">#43</div><span class="carc-badge co">CO 4</span></td><td><span class="denial-reason">Add-on code</span></td><td class="rarc-wrap"><div class="rarc-id">N122</div><div class="rarc-desc">Add-on code cannot be billed by itself.</div></td><td class="td-meaning">The claim was denied because an add-on procedure code (+ symbol in CPT, e.g., +11045, +69990) was billed alone without its required primary/base procedure code on the same claim. Add-on codes are never payable independently; they must accompany the primary service they supplement.</td><td><div class="chip-row"><span class="chip chip-green">49568 (hernia mesh implantation) billed alone without a primary hernia repair code (e.g., 49560–49566) → denied.</span><span class="chip chip-green">15777 (grafting for wound closure) submitted without the primary closure/reconstruction code (e.g., 13100–13160 series).</span><span class="chip chip-green">69990 (microsurgical techniques) billed by itself instead of with the primary neurosurgical or ENT procedure.</span><span class="chip chip-green">99199 (unlisted special service) or +95972 (complex programming of neurostimulator) submitted standalone → rejected.</span><span class="chip chip-green">95971 (simple programming of neurostimulator) billed without the primary implantation code (e.g., 64555, 64561).</span><span class="chip chip-green">Anesthesia add-on time code or time-based add-on (e.g., +99354 prolonged service) submitted without base code.</span></div></td><td><div class="chip-row"><span class="chip chip-green">Add-on code (+XXXXX) submitted without corresponding primary/base procedure code.</span><span class="chip chip-green">Primary code omitted, on different claim, or not billed on same date of service.</span><span class="chip chip-green">Billing software or manual entry error (add-on code selected alone).</span><span class="chip chip-green">Provider unaware add-on codes require primary code on same claim.</span><span class="chip chip-green">Coding error: Misidentifying an add-on code as standalone or forgetting to pair it.</span><span class="chip chip-green">Claim split or resubmission error: Primary code processed earlier; add-on billed later without reference.</span><span class="chip chip-green">Lack of pre-billing check for required primary code linkage per CPT guidelines.</span></div></td><td class="td-res">• Identify add-on code from EOB and confirm primary code needed (CPT book or NCCI lookup).<br>• Verify primary procedure was performed and billed (same DOS, same claim).<br>• Resubmit corrected claim including both primary and add-on codes (frequency 7).<br>• If primary code already billed separately → appeal with claim history and documentation showing linkage.<br>• Accept denial if no primary procedure performed (post write-off).</td></tr>
A4: CO 4 | B4: Adjustment Due to Use of Non-Specific Procedure Code | C4: MA91—Alert: An adjustment was made because a more specific procedure code should have been billed | D4: This alert indicates that the claim was adjusted because a more specific procedure code should have been billed. The submitted CPT/HCPCS code was considered too general, non-specific, or not the most appropriate code for the service rendered. | E4: Unlisted or generic CPT code used when a specific code exists → claim adjusted. Broad procedure code billed instead of detailed code → reduced payment. Incorrect code selection despite available specific HCPCS → denial applied. Use of miscellaneous code without justification → claim rejected. Coding not updated to reflect current CPT specificity → adjustment issued. | F4: Use of non-specific or generic procedure codes. Lack of awareness of updated CPT/HCPCS codes. Incomplete coding knowledge or training. Failure to review coding guidelines. System defaults to general codes. Insufficient documentation to support specific code selection. | G4: Review clinical documentation for accurate coding. Identify the most specific CPT/HCPCS code applicable. Replace generic or incorrect code with appropriate specific code. Resubmit corrected claim if necessary. Appeal if correct code was used and supported by documentation. | I4: <tr data-carc="" data-type="" data-rarc="MA91 — Alert: This determination is the result of the appeal you filed." data-denial="" data-root=""><td><div class="row-num">#224</div><span class="carc-badge "></span></td><td><span class="denial-reason"></span></td><td class="rarc-wrap"><div class="rarc-id">MA91</div><div class="rarc-desc">Alert: This determination is the result of the appeal you filed.</div></td><td class="td-meaning"></td><td><div class="chip-row"></div></td><td><div class="chip-row"></div></td><td class="td-res"></td></tr>
A5: CO 151 | B5: Anesthesia Time Exceeds Allowed Maximum for Procedure | C5: N194—Anesthesia time exceeds the established maximum for this procedure | D5: The claim was adjusted or denied because the reported anesthesia time exceeds the maximum allowable time established by the payer for the specific procedure. Payers use standard anesthesia time guidelines, base units, and medical necessity criteria to determine appropriate reimbursement. If the billed time is significantly higher than expected for the procedure, the payer may reduce payment or deny the excess time as not reasonable or necessary. On the CMS-1500 claim form, anesthesia services are reported in Box 24D — CPT/HCPCS Codes (anesthesia codes) and Box 24G — Units (time units), which must align with documented anesthesia time. On the UB-04 claim form, anesthesia-related services may be reported in Form Locator (FL) 44 — HCPCS Code and FL 46 — Units, subject to payer limits. | E5: Anesthesia time billed significantly longer than typical for procedure → excess units denied. Incorrect time calculation (start/stop time error) → overbilling detected. Duplicate or overlapping anesthesia time submitted → adjustment applied. Procedure completed quickly but excessive time billed → denial issued. Documentation does not support billed anesthesia duration → claim reduced. | F5: Anesthesia time exceeds payer-established limits. Incorrect calculation of anesthesia time units. Documentation does not support billed duration. Duplicate or overlapping time entries. Lack of awareness of payer anesthesia guidelines. System or billing errors in unit reporting. | G5: Review anesthesia record for accurate start and end times. Verify correct calculation of time units per payer guidelines. Ensure documentation supports billed anesthesia duration. Correct units if overreported and resubmit claim. Appeal if extended time is medically necessary and documented. | I5: <tr data-carc="" data-type="" data-rarc="N194 — Technical component not paid if provider does not own the equipment used." data-denial="" data-root=""><td><div class="row-num">#315</div><span class="carc-badge "></span></td><td><span class="denial-reason"></span></td><td class="rarc-wrap"><div class="rarc-id">N194</div><div class="rarc-desc">Technical component not paid if provider does not own the equipment used.</div></td><td class="td-meaning"></td><td><div class="chip-row"></div></td><td><div class="chip-row"></div></td><td class="td-res"></td></tr>
A6: CO 45 | B6: ASC Quality Reporting Program Compliance | C6: N551—Alert: Payment adjusted based on a penalty for late filing | D6: The payment for this claim was adjusted based on the Ambulatory Surgical Center (ASC) Quality Reporting (ASCQR) Program) requirements. Under this Medicare program, ASCs must submit specified quality data measures to CMS. On the UB-04 claim form, ASC facility services are reported using Form Locator (FL) 4 — Type of Bill (usually 83X for ASC), FL 42 — Revenue Code, and FL 44 — HCPCS/Rate/HIPPS Code, which determine payment under the ASC fee schedule. Professional services billed on the CMS-1500 use Box 24D — Procedure Code for surgical services, but the quality reporting adjustment typically affects the facility payment. | E6: ASC failed to submit required quality reporting data → payment reduced. Incomplete submission of ASC quality measures → adjustment applied. Facility missed CMS reporting deadline → reimbursement penalty applied. ASC submitted incorrect or invalid reporting data → payment impacted. Quality reporting non-compliance detected during CMS review → claim adjusted. | F6: Failure to submit required ASCQR quality reporting measures. Incomplete or inaccurate quality data submission. Missed CMS reporting deadlines. Lack of internal tracking of reporting requirements. Miscommunication between clinical quality team and billing department. System not configured to capture required reporting data. | G6: Verify ASC participation status in the ASC Quality Reporting Program. Review CMS quality reporting submission records for compliance. Confirm whether the adjustment reflects a reporting penalty. Coordinate with quality/compliance team to address reporting gaps. Appeal only if the reporting data was submitted correctly but not recognized. | I6: <tr data-carc="" data-type="" data-rarc="N551 — Payment adjusted based on the Ambulatory Surgical Center (ASC) Quality Reporting Program." data-denial="" data-root=""><td><div class="row-num">#688</div><span class="carc-badge "></span></td><td><span class="denial-reason"></span></td><td class="rarc-wrap"><div class="rarc-id">N551</div><div class="rarc-desc">Payment adjusted based on the Ambulatory Surgical Center (ASC) Quality Reporting Program.</div></td><td class="td-meaning"></td><td><div class="chip-row"></div></td><td><div class="chip-row"></div></td><td class="td-res"></td></tr>
A7: CO 119 | B7: Benefit Exhausted | C7: N365—This benefit has been exhausted | D7: The claim was denied or adjusted because the patient has exhausted the available benefits for this service under their insurance plan. This means the patient has reached the maximum allowable limit, which may be based on number of visits, units, or total dollar amount within a defined benefit period. Once the benefit limit is reached, the payer will no longer reimburse for additional services of that type under the current plan period. | E7: Physical therapy visits exceed annual limit → additional visits denied. Chiropractic services exceed covered sessions → no payment issued. Mental health benefits reach maximum → further claims denied. DME benefit cap reached → additional rentals not covered. Dollar-based benefit maximum exceeded → claim denied. | F7: Benefit maximum reached (visits, units, or dollar limit). High utilization of limited services. Failure to track remaining benefits. Lack of eligibility and benefit verification. Plan-specific coverage limits exceeded. | G7: Verify benefit usage and remaining limits with payer. Confirm that benefit maximum has been reached. Check for secondary insurance or alternate coverage. Inform patient of financial responsibility. Appeal only if benefit exhaustion was applied incorrectly.
A8: CO 119 | B8: Benefit Exhausted for the Service | C8: N215—Alert: Under your applicable benefit plan, benefits have been exhausted for this service | D8: This alert indicates that benefits for the specific service have been exhausted under the patient’s plan. The payer has determined that the patient has already reached the maximum allowable limit (e.g., visit limits, dollar limits, or service caps) for this benefit. As a result, no further payment will be made for additional services of this type under the current plan. | E8: Physical therapy visit limit reached → additional visits denied. Chiropractic care exceeds annual maximum → no payment issued. Mental health sessions exceed plan limit → claim denied. DME rental capped → further billing not covered. Service utilization exceeds dollar or unit cap → denial applied. | F8: Physical therapy visit limit reached → additional visits denied. Chiropractic care exceeds annual maximum → no payment issued. Mental health sessions exceed plan limit → claim denied. DME rental capped → further billing not covered. Service utilization exceeds dollar or unit cap → denial applied. | G8: Benefit maximum limit reached. High utilization of limited services. Lack of tracking of remaining benefits. Failure to verify benefit limits prior to service. Plan-specific service caps exceeded. | I8: <tr data-carc="" data-type="" data-rarc="N215 — Alert: A payer providing supplemental or secondary coverage shall not require a claims determination for this service from a primary payer as a condition of making its own claims determination." data-denial="" data-root=""><td><div class="row-num">#338</div><span class="carc-badge "></span></td><td><span class="denial-reason"></span></td><td class="rarc-wrap"><div class="rarc-id">N215</div><div class="rarc-desc">Alert: A payer providing supplemental or secondary coverage shall not require a claims determination for this service from a primary payer as a condition of making its own claims determination.</div></td><td class="td-meaning"></td><td><div class="chip-row"></div></td><td><div class="chip-row"></div></td><td class="td-res"></td></tr>
A9: CO 119 | B9: Benefit Maximum | C9: M90—Not covered when performed more than once within a 12-month period | D9: The claim was denied because the payer allows coverage for this service only once within a 12-month period, and records indicate the patient already received the same or similar service during that timeframe. Frequency limitations are applied to prevent duplicate or unnecessary services unless medical necessity or exception criteria are met. | E9: • Annual screening test billed twice within the same year → denied. • Preventive exam performed again before 12 months from prior visit → denial issued. • Diagnostic service repeated within frequency window without medical necessity → denied. • DME supply replacement billed earlier than annual allowance → denial applied. • Procedure submitted again due to scheduling error or duplicate billing → payer denies second claim. | F9: • Service repeated within payer frequency limitation period. • Failure to verify patient service history prior to billing or scheduling. • Missing documentation supporting medical necessity for repeat service. • Incorrect coding (screening vs diagnostic) triggering frequency edit. • Duplicate claim submission or resubmission without correction indicator. • Staff unaware of payer frequency rules. | G9: • Review prior claim history and confirm date of previously paid service. • Determine whether repeat service qualifies for medical necessity exception. • If appropriate → appeal with documentation supporting necessity or clinical indication. • Correct coding if service should be diagnostic rather than routine screening. • If denial valid → transfer responsibility to patient only if proper notification obtained. • Adjust or void duplicate claim if submitted in error. | I9: <tr data-carc="CO 119" data-type="co" data-rarc="M90 — Not covered more than once in a 12 month period." data-denial="The claim was denied because the payer allows coverage for this service only once within a 12-month period, and records indicate the patient already received the same or similar service during that timeframe. Frequency limitations are applied to prevent duplicate or unnecessary services unless medical necessity or exception criteria are met." data-root="• Service repeated within payer frequency limitation period.\n• Failure to verify patient service history prior to billing or scheduling.\n• Missing documentation supporting medical necessity for repeat service.\n• Incorrect coding (screening vs diagnostic) triggering frequency edit.\n• Duplicate claim submission or resubmission without correction indicator.\n• Staff unaware of payer frequency rules."><td><div class="row-num">#133</div><span class="carc-badge co">CO 119</span></td><td><span class="denial-reason">Benefit Maximum</span></td><td class="rarc-wrap"><div class="rarc-id">M90</div><div class="rarc-desc">Not covered more than once in a 12 month period.</div></td><td class="td-meaning">The claim was denied because the payer allows coverage for this service only once within a 12-month period, and records indicate the patient already received the same or similar service during that timeframe. Frequency limitations are applied to prevent duplicate or unnecessary services unless medical necessity or exception criteria are met.</td><td><div class="chip-row"><span class="chip chip-green">Annual screening test billed twice within the same year → denied.</span><span class="chip chip-green">Preventive exam performed again before 12 months from prior visit → denial issued.</span><span class="chip chip-green">Diagnostic service repeated within frequency window without medical necessity → denied.</span><span class="chip chip-green">DME supply replacement billed earlier than annual allowance → denial applied.</span><span class="chip chip-green">Procedure submitted again due to scheduling error or duplicate billing → payer denies second claim.</span></div></td><td><div class="chip-row"><span class="chip chip-green">Service repeated within payer frequency limitation period.</span><span class="chip chip-green">Failure to verify patient service history prior to billing or scheduling.</span><span class="chip chip-green">Missing documentation supporting medical necessity for repeat service.</span><span class="chip chip-green">Incorrect coding (screening vs diagnostic) triggering frequency edit.</span><span class="chip chip-green">Duplicate claim submission or resubmission without correction indicator.</span><span class="chip chip-green">Staff unaware of payer frequency rules.</span></div></td><td class="td-res">• Review prior claim history and confirm date of previously paid service.<br>• Determine whether repeat service qualifies for medical necessity exception.<br>• If appropriate → appeal with documentation supporting necessity or clinical indication.<br>• Correct coding if service should be diagnostic rather than routine screening.<br>• If denial valid → transfer responsibility to patient only if proper notification obtained.<br>• Adjust or void duplicate claim if submitted in error.</td></tr>
A10: CO 119 | B10: Benefit Maximum | C10: N362—The number of Days or Units of Service exceeds our acceptable maximum | D10: The claim was denied or adjusted because the billed number of days, units, visits, or services exceeds the payer's allowable maximum limit for a specified time period, benefit category, or per-episode/per-year cap. The payer enforces strict quantitative restrictions (e.g., maximum visits per year, units per day, sessions per authorization) as defined in the patient's benefit plan, medical policy, or coverage guidelines. | E10: • Physical therapy billed 30 units/visits; plan limits 20 per year → denied for 10 excess units. • Home health aide services billed 45 days in episode; Medicare or plan caps at 30 days → excess days denied. • Chiropractic adjustments billed 40 visits; payer allows maximum 26 per year → denied for 14 over limit. • Mental health therapy sessions (e.g., 90837) billed 25 per year; benefit max 15 → excess sessions patient responsibility. • Dialysis sessions or infusion therapy exceed per-month or per-episode cap → over-limit units adjusted. | F10: • Billed units/days/visits exceed the plan's hard limit (per year, per episode, per authorization, or per lifetime). • No prior check of benefit maximums during eligibility verification or pre-service authorization. • Authorization approved for fewer units/days than billed (e.g., auth for 12 PT visits; billed 18). • Benefit cap reset not accounted for (e.g., new calendar year but patient used prior-year limit). • Billing software or superbills not tracking or flagging benefit maximums per patient/plan. • Provider continued services beyond plan limit without patient consent or additional authorization. | G10: • Verify billed units/days against the cap and any prior authorization limits (check auth letter or payer portal). • If error in billing (e.g., typo in units) → Correct claim to stay within limit and resubmit (frequency 7 replacement/corrected). • If excess justified (e.g., medical necessity) → Appeal with documentation (e.g., progress notes, physician letter justifying additional units) and request exception. • If limit reached → Post write-off for excess amount; bill patient for over-limit portion (after notifying and obtaining consent). • Obtain retroactive authorization for additional units if payer allows; resubmit once updated. | I10: <tr data-carc="CO 119" data-type="co" data-rarc="N362 — The number of Days or Units of Service exceeds our acceptable maximum." data-denial="The claim was denied or adjusted because the billed number of days, units, visits, or services exceeds the payer's allowable maximum limit for a specified time period, benefit category, or per-episode/per-year cap. The payer enforces strict quantitative restrictions (e.g., maximum visits per year, units per day, sessions per authorization) as defined in the patient's benefit plan, medical policy, or coverage guidelines." data-root="• Billed units/days/visits exceed the plan's hard limit (per year, per episode, per authorization, or per lifetime).\n• No prior check of benefit maximums during eligibility verification or pre-service authorization.\n• Authorization approved for fewer units/days than billed (e.g., auth for 12 PT visits; billed 18).\n• Benefit cap reset not accounted for (e.g., new calendar year but patient used prior-year limit).\n• Billing software or superbills not tracking or flagging benefit maximums per patient/plan.\n• Provider continued services beyond plan limit without patient consent or additional authorization."><td><div class="row-num">#47</div><span class="carc-badge co">CO 119</span></td><td><span class="denial-reason">Benefit Maximum</span></td><td class="rarc-wrap"><div class="rarc-id">N362</div><div class="rarc-desc">The number of Days or Units of Service exceeds our acceptable maximum.</div></td><td class="td-meaning">The claim was denied or adjusted because the billed number of days, units, visits, or services exceeds the payer's allowable maximum limit for a specified time period, benefit category, or per-episode/per-year cap. The payer enforces strict quantitative restrictions (e.g., maximum visits per year, units per day, sessions per authorization) as defined in the patient's benefit plan, medical policy, or coverage guidelines.</td><td><div class="chip-row"><span class="chip chip-green">Physical therapy billed 30 units/visits; plan limits 20 per year → denied for 10 excess units.</span><span class="chip chip-green">Home health aide services billed 45 days in episode; Medicare or plan caps at 30 days → excess days denied.</span><span class="chip chip-green">Chiropractic adjustments billed 40 visits; payer allows maximum 26 per year → denied for 14 over limit.</span><span class="chip chip-green">Mental health therapy sessions (e.g., 90837) billed 25 per year; benefit max 15 → excess sessions patient responsibility.</span><span class="chip chip-green">Dialysis sessions or infusion therapy exceed per-month or per-episode cap → over-limit units adjusted.</span></div></td><td><div class="chip-row"><span class="chip chip-green">Billed units/days/visits exceed the plan's hard limit (per year, per episode, per authorization, or per lifetime).</span><span class="chip chip-green">No prior check of benefit maximums during eligibility verification or pre-service authorization.</span><span class="chip chip-green">Authorization approved for fewer units/days than billed (e.g., auth for 12 PT visits; billed 18).</span><span class="chip chip-green">Benefit cap reset not accounted for (e.g., new calendar year but patient used prior-year limit).</span><span class="chip chip-green">Billing software or superbills not tracking or flagging benefit maximums per patient/plan.</span><span class="chip chip-green">Provider continued services beyond plan limit without patient consent or additional authorization.</span></div></td><td class="td-res">• Verify billed units/days against the cap and any prior authorization limits (check auth letter or payer portal).<br>• If error in billing (e.g., typo in units) → Correct claim to stay within limit and resubmit (frequency 7 replacement/corrected).<br>• If excess justified (e.g., medical necessity) → Appeal with documentation (e.g., progress notes, physician letter justifying additional units) and request exception.<br>• If limit reached → Post write-off for excess amount; bill patient for over-limit portion (after notifying and obtaining consent).<br>• Obtain retroactive authorization for additional units if payer allows; resubmit once updated.</td></tr>
A11: CO 119 | B11: Benefit Maximum Reached | C11: N131—Alert: Total payments under this benefit have reached the benefit maximum. Submit future claims to the next plan tier. | D11: This alert indicates that the total allowable payments under the current benefit plan have reached the maximum limit. | E11: Physical therapy visits exceed annual limit → further claims denied. Chiropractic care maximum reached → no additional payment under plan. Mental health session cap exceeded → claim denied for remaining visits. Patient transitions from primary plan to secondary tier → billing shift required. Benefit exhausted mid-treatment → remaining services not covered under current plan. | F11: Benefit maximum limit reached under plan. High utilization of limited services (e.g., therapy visits). Lack of tracking of benefit usage. No awareness of plan-specific limits. Failure to verify remaining benefits before service | G11: Verify benefit usage and maximum limits with payer. Identify if secondary or next-tier coverage is available. Submit subsequent claims to appropriate payer/plan tier. Inform patient of benefit exhaustion and financial responsibility. Appeal only if benefit maximum was applied incorrectly. | I11: <tr data-carc="" data-type="" data-rarc="N131 — Total payments under multiple contracts cannot exceed the allowance for this service." data-denial="" data-root=""><td><div class="row-num">#259</div><span class="carc-badge "></span></td><td><span class="denial-reason"></span></td><td class="rarc-wrap"><div class="rarc-id">N131</div><div class="rarc-desc">Total payments under multiple contracts cannot exceed the allowance for this service.</div></td><td class="td-meaning"></td><td><div class="chip-row"></div></td><td><div class="chip-row"></div></td><td class="td-res"></td></tr>
A12: CO 119 | B12: Benefit Payments Ending Due to Expiration of Payment Cycle | C12: N132—Alert: Payments will cease for this benefit upon the expiration of this payment cycle. | D12: This alert indicates that payments for this benefit will stop once the current payment cycle or benefit period expires. | E12: Therapy services covered until end of annual benefit cycle → future visits denied after expiration. Home health episode nearing end date → payments cease after cycle completion. Contractual benefit period ending → no further reimbursement beyond cycle. Patient continues treatment beyond covered timeframe → claims denied. Payer notifies provider of upcoming benefit termination → alert issued. | F12: Benefit tied to a defined payment cycle or timeframe. Approaching end of coverage period (annual, episode-based, or contractual). Lack of awareness of benefit expiration timelines. Failure to track benefit periods. Continued services beyond covered timeframe. | G12: Verify benefit period and expiration date with payer. Ensure services are billed within active coverage period. Identify alternative coverage or next benefit tier if available. Inform patient of upcoming benefit expiration. Adjust treatment or billing plan accordingly. Appeal only if payment cycle was applied incorrectly. | I12: <tr data-carc="" data-type="" data-rarc="N132 — Alert: Payments will cease for services rendered by this US Government debarred or excluded provider after the 30 day grace period as previously notified." data-denial="" data-root=""><td><div class="row-num">#260</div><span class="carc-badge "></span></td><td><span class="denial-reason"></span></td><td class="rarc-wrap"><div class="rarc-id">N132</div><div class="rarc-desc">Alert: Payments will cease for services rendered by this US Government debarred or excluded provider after the 30 day grace period as previously notified.</div></td><td class="td-meaning"></td><td><div class="chip-row"></div></td><td><div class="chip-row"></div></td><td class="td-res"></td></tr>
A13: CO 97 | B13: Bundling | C13: M14—The patient has a condition previously denied for this procedure/service | D13: No separate payment allowed for an injection given during an office visit. If the patient only received an injection (no significant E/M service), the office visit is also not payable. The injection is bundled into the visit or considered the primary service. | E13: • Patient seen only for injection (e.g., corticosteroid 20610) → E/M visit (99213) denied. • Office visit + injection billed; payer bundles injection into visit → no separate payment for injection. • Minor E/M + therapeutic injection same day → E/M denied if not significant/separately identifiable. | F13: • Injection billed separately when considered part of office visit. • No significant, separately identifiable E/M service documented (missing -25 modifier). • Patient visit solely for injection → no billable E/M component. • Provider unaware of bundling rules for injections during office visits. | G13: • Review documentation: Confirm if significant E/M occurred (history, exam, decision-making beyond injection). • If significant E/M → resubmit with -25 modifier on E/M code. • If only injection → accept denial for E/M and keep injection payment (or vice versa). • Appeal with detailed notes proving separate E/M service if -25 justified. | I13: <tr data-carc="CO 97" data-type="co" data-rarc="M14 — No separate payment for an injection administered during an office visit, and no payment for a full office visit if the patient only received an injection." data-denial="No separate payment allowed for an injection given during an office visit. If the patient only received an injection (no significant E/M service), the office visit is also not payable. The injection is bundled into the visit or considered the primary service." data-root="• Injection billed separately when considered part of office visit.\n• No significant, separately identifiable E/M service documented (missing -25 modifier).\n• Patient visit solely for injection → no billable E/M component.\n• Provider unaware of bundling rules for injections during office visits."><td><div class="row-num">#78</div><span class="carc-badge co">CO 97</span></td><td><span class="denial-reason">Bundling</span></td><td class="rarc-wrap"><div class="rarc-id">M14</div><div class="rarc-desc">No separate payment for an injection administered during an office visit, and no payment for a full office visit if the patient only received an injection.</div></td><td class="td-meaning">No separate payment allowed for an injection given during an office visit. If the patient only received an injection (no significant E/M service), the office visit is also not payable. The injection is bundled into the visit or considered the primary service.</td><td><div class="chip-row"><span class="chip chip-green">Patient seen only for injection (e.g., corticosteroid 20610) → E/M visit (99213) denied.</span><span class="chip chip-green">Office visit + injection billed; payer bundles injection into visit → no separate payment for injection.</span><span class="chip chip-green">Minor E/M + therapeutic injection same day → E/M denied if not significant/separately identifiable.</span></div></td><td><div class="chip-row"><span class="chip chip-green">Injection billed separately when considered part of office visit.</span><span class="chip chip-green">No significant, separately identifiable E/M service documented (missing -25 modifier).</span><span class="chip chip-green">Patient visit solely for injection → no billable E/M component.</span><span class="chip chip-green">Provider unaware of bundling rules for injections during office visits.</span></div></td><td class="td-res">• Review documentation: Confirm if significant E/M occurred (history, exam, decision-making beyond injection).<br>• If significant E/M → resubmit with -25 modifier on E/M code.<br>• If only injection → accept denial for E/M and keep injection payment (or vice versa).<br>• Appeal with detailed notes proving separate E/M service if -25 justified.</td></tr>
A14: CO 16 | B14: Bundling | C14: M12—Diagnostic tests performed by a physician who also provided the interpretation must indicate whether the test was purchased or performed | D14: Physician must indicate on the claim if any part of the diagnostic test (technical component) was purchased/outsourced. | E14: • ECG or X-ray global billing without marking purchased services. • Lab/radiology outsourced; claim lacks indicator. • Interpretation-only billing without disclosing purchased component. | F14: • Box 20 (CMS-1500) left blank or “No” when services were purchased. • No equivalent indicator on UB-04 (FL 39–41 or remarks). • Billing software did not prompt for purchased service disclosure. | G14: • Check Box 20 on CMS-1500 (or UB-04 equivalent) for purchased services indicator. • Correct claim: Mark “Yes” in Box 20 (CMS-1500) and enter purchased amount if required. • Resubmit corrected claim (frequency 7). • Appeal with documentation showing purchased vs. performed components. | I14: <tr data-carc="CO 16" data-type="co" data-rarc="M12 — Diagnostic tests performed by a physician must indicate whether purchased services are included on the claim." data-denial="Physician must indicate on the claim if any part of the diagnostic test (technical component) was purchased/outsourced." data-root="• Box 20 (CMS-1500) left blank or “No” when services were purchased.\n• No equivalent indicator on UB-04 (FL 39–41 or remarks).\n• Billing software did not prompt for purchased service disclosure."><td><div class="row-num">#66</div><span class="carc-badge co">CO 16</span></td><td><span class="denial-reason">Bundling</span></td><td class="rarc-wrap"><div class="rarc-id">M12</div><div class="rarc-desc">Diagnostic tests performed by a physician must indicate whether purchased services are included on the claim.</div></td><td class="td-meaning">Physician must indicate on the claim if any part of the diagnostic test (technical component) was purchased/outsourced.</td><td><div class="chip-row"><span class="chip chip-green">ECG or X-ray global billing without marking purchased services.</span><span class="chip chip-green">Lab/radiology outsourced; claim lacks indicator.</span><span class="chip chip-green">Interpretation-only billing without disclosing purchased component.</span></div></td><td><div class="chip-row"><span class="chip chip-green">Box 20 (CMS-1500) left blank or “No” when services were purchased.</span><span class="chip chip-green">No equivalent indicator on UB-04 (FL 39–41 or remarks).</span><span class="chip chip-green">Billing software did not prompt for purchased service disclosure.</span></div></td><td class="td-res">• Check Box 20 on CMS-1500 (or UB-04 equivalent) for purchased services indicator.<br>• Correct claim: Mark “Yes” in Box 20 (CMS-1500) and enter purchased amount if required.<br>• Resubmit corrected claim (frequency 7).<br>• Appeal with documentation showing purchased vs. performed components.</td></tr>
A15: CO 97 | B15: Bundling | C15: M3—Equipment is the same or similar to equipment already being used | D15: The claim was denied because the payer determined that the Durable Medical Equipment (DME) being billed is the same as, or similar to, equipment the patient already owns or is currently renting. Coverage is not allowed for duplicate or overlapping equipment within the same reasonable useful lifetime (RUL) or rental period. | E15: • Patient already has a wheelchair on file within the reasonable useful lifetime, and a new wheelchair is billed → denied as same/similar equipment. • CPAP device billed while another supplier is still in active rental period → denied due to existing equipment rental. • Replacement hospital bed billed before the 5-year reasonable useful lifetime expired without medical justification → denial issued. • Oxygen equipment billed by a new provider when patient is still under capped rental with another supplier → denied. • Orthotic brace billed when a similar brace was previously provided recently → payer denies as duplicate equipment. | F15: • Eligibility verification for prior equipment ownership or rental status was not performed before billing. • Patient transferred from another supplier but prior equipment rental period still active. • Replacement equipment billed without documentation of medical necessity, damage, or change in condition. • Incorrect HCPCS coding causing payer to classify equipment as same/similar. • Lack of coordination between providers regarding existing DME history. • Missing documentation supporting replacement due to loss, theft, or irreparable damage. | G15: • Verify patient DME history through payer portal, Medicare IVR, or documentation from prior supplier. • Confirm whether the patient owns equipment or is still in rental period with another provider. • If replacement is medically necessary → submit documentation supporting change in condition, damage, or non-functionality. • Obtain and submit physician order and medical necessity records supporting need for different equipment. • If patient changed suppliers during rental period → coordinate billing transfer according to payer rules. • Appeal with documentation showing equipment is not same/similar (different HCPCS, upgraded need, or medical change). | I15: <tr data-carc="CO 97" data-type="co" data-rarc="M3 — Equipment is the same or similar to equipment already being used." data-denial="The claim was denied because the payer determined that the Durable Medical Equipment (DME) being billed is the same as, or similar to, equipment the patient already owns or is currently renting. Coverage is not allowed for duplicate or overlapping equipment within the same reasonable useful lifetime (RUL) or rental period." data-root="• Eligibility verification for prior equipment ownership or rental status was not performed before billing.\n• Patient transferred from another supplier but prior equipment rental period still active.\n• Replacement equipment billed without documentation of medical necessity, damage, or change in condition.\n• Incorrect HCPCS coding causing payer to classify equipment as same/similar.\n• Lack of coordination between providers regarding existing DME history.\n• Missing documentation supporting replacement due to loss, theft, or irreparable damage."><td><div class="row-num">#95</div><span class="carc-badge co">CO 97</span></td><td><span class="denial-reason">Bundling</span></td><td class="rarc-wrap"><div class="rarc-id">M3</div><div class="rarc-desc">Equipment is the same or similar to equipment already being used.</div></td><td class="td-meaning">The claim was denied because the payer determined that the Durable Medical Equipment (DME) being billed is the same as, or similar to, equipment the patient already owns or is currently renting. Coverage is not allowed for duplicate or overlapping equipment within the same reasonable useful lifetime (RUL) or rental period.</td><td><div class="chip-row"><span class="chip chip-green">Patient already has a wheelchair on file within the reasonable useful lifetime, and a new wheelchair is billed → denied as same/similar equipment.</span><span class="chip chip-green">CPAP device billed while another supplier is still in active rental period → denied due to existing equipment rental.</span><span class="chip chip-green">Replacement hospital bed billed before the 5-year reasonable useful lifetime expired without medical justification → denial issued.</span><span class="chip chip-green">Oxygen equipment billed by a new provider when patient is still under capped rental with another supplier → denied.</span><span class="chip chip-green">Orthotic brace billed when a similar brace was previously provided recently → payer denies as duplicate equipment.</span></div></td><td><div class="chip-row"><span class="chip chip-green">Eligibility verification for prior equipment ownership or rental status was not performed before billing.</span><span class="chip chip-green">Patient transferred from another supplier but prior equipment rental period still active.</span><span class="chip chip-green">Replacement equipment billed without documentation of medical necessity, damage, or change in condition.</span><span class="chip chip-green">Incorrect HCPCS coding causing payer to classify equipment as same/similar.</span><span class="chip chip-green">Lack of coordination between providers regarding existing DME history.</span><span class="chip chip-green">Missing documentation supporting replacement due to loss, theft, or irreparable damage.</span></div></td><td class="td-res">• Verify patient DME history through payer portal, Medicare IVR, or documentation from prior supplier.<br>• Confirm whether the patient owns equipment or is still in rental period with another provider.<br>• If replacement is medically necessary → submit documentation supporting change in condition, damage, or non-functionality.<br>• Obtain and submit physician order and medical necessity records supporting need for different equipment.<br>• If patient changed suppliers during rental period → coordinate billing transfer according to payer rules.<br>• Appeal with documentation showing equipment is not same/similar (different HCPCS, upgraded need, or medical change).</td></tr>
